Workbook

Sheet PLANTILLA
C1: TOTALES | E1: =SUM(E3:E6987) -> 66427.31 | F1: =SUM(F3:F6987) -> 66427.31 | J1: =E1-F1 -> -3.3469405e-10 | AH1: NO INGRESAR DATOS EN ESTAS CELDAS
A2: Origen | B2: Num.Voucher | C2: Fecha de Liquidacion | D2: Cuenta | E2: Monto Debe | F2: Monto Haber | G2: Moneda S/D | H2: T.Cambio | I2: Doc | J2: Num.Doc | K2: Fec.Doc | L2: Fec.Ven | M2: RUC O DNI | N2: C.Costo | O2: Presupuesto | P2: F.Efectivo | Q2: Glosa | R2: Libro C/V/R | S2: Mto.Neto 1 | T2: Mto.Neto 2 | U2: Mto.Neto 3 | V2: Mto.Neto 4 | W2: Mto.Neto 5 | X2: Mto.Neto 6 | Y2: Mto.Neto 7 | Z2: Mto.Neto 8 | AA2: Mto.Neto 9 | AB2: Mto.IGV | AC2: Ref.Doc | AD2: Ref.Num.Doc | AE2: Ref.Fecha | AF2: Det.Num | AG2: Det.Fecha | AH2: RUC O DNI | AI2: R. Social | AJ2: Tipo | AK2: Tip.Doc.Iden | AL2: Medio de Pago | AM2: Apellido 1 | AN2: Apellido 2 | AO2: Nombre | AP2: T.Bien
A3: 15 | B3: 01 | C3: 46174 | D3: 14132 | F3: 500 | G3: S | H3: 3.417 | I3: PL | J3: 3626 | K3: 46167 | L3: 46167 | M3: 05387728 | Q3: MENDOZA/PUCALLPA-MOYOBAMBA-PUCALLPA/CKW767/EXCESO (0) | AH3: =M3 -> 05387728 | AI3: =IFERROR(INDEX(PROVEEDORES!$B$1:$B$6940,MATCH(AH3,PROVEEDORES!$A$1:$A$6940,0)),"") -> MENDOZA VARGAS RAUL
A4: 15 | B4: 01 | C4: 46174 | D4: 14132 | F4: 113.4 | G4: S | H4: 3.417 | I4: PL | J4: 3693 | K4: 46174 | L4: 46174 | M4: 05387728 | Q4: POR LIQUIDAR | AH4: =M4 -> 05387728 | AI4: =IFERROR(INDEX(PROVEEDORES!$B$1:$B$6940,MATCH(AH4,PROVEEDORES!$A$1:$A$6940,0)),"") -> MENDOZA VARGAS RAUL
A5: 15 | B5: 01 | C5: 46174 | D5: 42121 | E5: 52.2 | G5: S | H5: 3.417 | I5: 01 | J5: FH02-599324 | K5: 46172 | L5: 46172 | M5: 20511004251 | Q5: PEAJE | AH5: =M5 -> 20511004251 | AI5: =IFERROR(INDEX(PROVEEDORES!$B$1:$B$6940,MATCH(AH5,PROVEEDORES!$A$1:$A$6940,0)),"") -> CONCESIONARIA IIRSA NORTE S.A.
A6: 15 | B6: 01 | C6: 46174 | D6: 42121 | E6: 52.2 | G6: S | H6: 3.417 | I6: 01 | J6: FH01-511823 | K6: 46172 | L6: 46172 | M6: 20511004251 | Q6: PEAJE | AH6: =M6 -> 20511004251 | AI6: =IFERROR(INDEX(PROVEEDORES!$B$1:$B$6940,MATCH(AH6,PROVEEDORES!$A$1:$A$6940,0)),"") -> CONCESIONARIA IIRSA NORTE S.A.
A7: 15 | B7: 01 | C7: 46174 | D7: 42121 | E7: 20 | G7: S | H7: 3.417 | I7: 01 | J7: E001-3991 | K7: 46167 | L7: 46167 | M7: 10762857575 | Q7: AFLOJATODO | AH7: =M7 -> 10762857575 | AI7: =IFERROR(INDEX(PROVEEDORES!$B$1:$B$6940,MATCH(AH7,PROVEEDORES!$A$1:$A$6940,0)),"") -> FLORES HOYOS SIOMI LUCERO
A8: 15 | B8: 01 | C8: 46174 | D8: 42121 | E8: 40 | G8: S | H8: 3.417 | I8: 01 | J8: E001-240 | K8: 46174 | L8: 46174 | M8: 10713390793 | Q8: REPARACION DE LLANTA | AH8: =M8 -> 10713390793 | AI8: =IFERROR(INDEX(PROVEEDORES!$B$1:$B$6940,MATCH(AH8,PROVEEDORES!$A$1:$A$6940,0)),"") -> PADILLA MELENDEZ JOSE VALENTINO
A9: 15 | B9: 01 | C9: 46174 | D9: 42121 | E9: 40 | G9: S | H9: 3.417 | I9: 01 | J9: FF01-4607 | K9: 46174 | L9: 46174 | M9: 10755996551 | Q9: LAVADO | AH9: =M9 -> 10755996551 | AI9: =IFERROR(INDEX(PROVEEDORES!$B$1:$B$6940,MATCH(AH9,PROVEEDORES!$A$1:$A$6940,0)),"") -> PEREZ DAHUA FRANS DENNIS
A10: 15 | B10: 01 | C10: 46174 | D10: 42121 | E10: 49 | G10: S | H10: 3.417 | I10: 01 | J10: FF01-4609 | K10: 46174 | L10: 46174 | M10: 10755996551 | Q10: ARREGLO DE CARGA | AH10: =M10 -> 10755996551 | AI10: =IFERROR(INDEX(PROVEEDORES!$B$1:$B$6940,MATCH(AH10,PROVEEDORES!$A$1:$A$6940,0)),"") -> PEREZ DAHUA FRANS DENNIS
A11: 15 | B11: 01 | C11: 46174 | D11: 63433 | E11: 40 | G11: S | H11: 3.417 | I11: 03 | J11: 0001-000059 | K11: 46172 | L11: 46172 | M11: 10009448239 | Q11: REPARACION DE LLANTA | AH11: =M11 -> 10009448239 | AI11: =IFERROR(INDEX(PROVEEDORES!$B$1:$B$6940,MATCH(AH11,PROVEEDORES!$A$1:$A$6940,0)),"") -> LUNA PANDURO GUILLERMO
A12: 15 | B12: 01 | C12: 46174 | D12: 6314 | E12: 40 | G12: S | H12: 3.417 | I12: 03 | J12: 0001-043570 | K12: 46167 | L12: 46167 | M12: 10446876312 | Q12: CONSUMO | AH12: =M12 -> 10446876312 | AI12: =IFERROR(INDEX(PROVEEDORES!$B$1:$B$6940,MATCH(AH12,PROVEEDORES!$A$1:$A$6940,0)),"") -> IRENE ELENITH ROJAS RUIZ
A13: 15 | B13: 01 | C13: 46174 | D13: 6314 | E13: 40 | G13: S | H13: 3.417 | I13: 03 | J13: 0001-004202 | K13: 46168 | L13: 46168 | M13: 10414823080 | Q13: CONSUMO | AH13: =M13 -> 10414823080 | AI13: =IFERROR(INDEX(PROVEEDORES!$B$1:$B$6940,MATCH(AH13,PROVEEDORES!$A$1:$A$6940,0)),"") -> TOLENTINO SIMON REINA
A14: 15 | B14: 01 | C14: 46174 | D14: 6314 | E14: 40 | G14: S | H14: 3.417 | I14: 03 | J14: 0001-004210 | K14: 46169 | L14: 46169 | M14: 10414823080 | Q14: CONSUMO | AH14: =M14 -> 10414823080 | AI14: =IFERROR(INDEX(PROVEEDORES!$B$1:$B$6940,MATCH(AH14,PROVEEDORES!$A$1:$A$6940,0)),"") -> TOLENTINO SIMON REINA
A15: 15 | B15: 01 | C15: 46174 | D15: 6314 | E15: 40 | G15: S | H15: 3.417 | I15: 03 | J15: 0003-000507 | K15: 46170 | L15: 46170 | M15: 10804598184 | Q15: CONSUMO | AH15: =M15 -> 10804598184 | AI15: =IFERROR(INDEX(PROVEEDORES!$B$1:$B$6940,MATCH(AH15,PROVEEDORES!$A$1:$A$6940,0)),"") -> RODRIGUEZ SAAVEDRA VICTORIA
A16: 15 | B16: 01 | C16: 46174 | D16: 6314 | E16: 40 | G16: S | H16: 3.417 | I16: 03 | J16: 0002-001172 | K16: 46171 | L16: 46171 | M16: 10011321840 | Q16: CONSUMO | AH16: =M16 -> 10011321840 | AI16: =IFERROR(INDEX(PROVEEDORES!$B$1:$B$6940,MATCH(AH16,PROVEEDORES!$A$1:$A$6940,0)),"") -> PIRO RENGIFO GUILLERMO
A17: 15 | B17: 01 | C17: 46174 | D17: 6314 | E17: 40 | G17: S | H17: 3.417 | I17: 03 | J17: 0001-0004611 | K17: 46172 | L17: 46172 | M17: 10718880063 | Q17: CONSUMO | AH17: =M17 -> 10718880063 | AI17: =IFERROR(INDEX(PROVEEDORES!$B$1:$B$6940,MATCH(AH17,PROVEEDORES!$A$1:$A$6940,0)),"") -> DIAZ VILLALOBOS DIMAS
A18: 15 | B18: 01 | C18: 46174 | D18: 6314 | E18: 40 | G18: S | H18: 3.417 | I18: 03 | J18: 0003-000514 | K18: 46173 | L18: 46173 | M18: 10804598184 | Q18: CONSUMO | AH18: =M18 -> 10804598184 | AI18: =IFERROR(INDEX(PROVEEDORES!$B$1:$B$6940,MATCH(AH18,PROVEEDORES!$A$1:$A$6940,0)),"") -> RODRIGUEZ SAAVEDRA VICTORIA
A19: 15 | B19: 01 | C19: 46174 | D19: 6314 | E19: 40 | G19: S | H19: 3.417 | I19: 03 | J19: 0001-004224 | K19: 46174 | L19: 46174 | M19: 10414823080 | Q19: CONSUMO | AH19: =M19 -> 10414823080 | AI19: =IFERROR(INDEX(PROVEEDORES!$B$1:$B$6940,MATCH(AH19,PROVEEDORES!$A$1:$A$6940,0)),"") -> TOLENTINO SIMON REINA
A20: 15 | B20: 02 | C20: 46174 | D20: 14132 | F20: 750 | G20: S | H20: 3.417 | I20: PL | J20: 3598 | K20: 46163 | L20: 46163 | M20: 10499879 | Q20: VEGA/PUCALLPA-JAEN-PUCALLPA/CKW716/EXCESO (0) | AH20: =M20 -> 10499879 | AI20: =IFERROR(INDEX(PROVEEDORES!$B$1:$B$6940,MATCH(AH20,PROVEEDORES!$A$1:$A$6940,0)),"") -> VEGA JANAMPA HECTOR HUGO
A21: 15 | B21: 02 | C21: 46174 | D21: 14132 | F21: 80 | G21: S | H21: 3.417 | I21: PL | J21: 3651 | K21: 46170 | L21: 46170 | M21: 10499879 | Q21: POR LIQUIDAR | AH21: =M21 -> 10499879 | AI21: =IFERROR(INDEX(PROVEEDORES!$B$1:$B$6940,MATCH(AH21,PROVEEDORES!$A$1:$A$6940,0)),"") -> VEGA JANAMPA HECTOR HUGO
A22: 15 | B22: 02 | C22: 46174 | D22: 14132 | F22: 176.2 | G22: S | H22: 3.417 | I22: PL | J22: 3686 | K22: 46174 | L22: 46174 | M22: 10499879 | Q22: POR LIQUIDAR | AH22: =M22 -> 10499879 | AI22: =IFERROR(INDEX(PROVEEDORES!$B$1:$B$6940,MATCH(AH22,PROVEEDORES!$A$1:$A$6940,0)),"") -> VEGA JANAMPA HECTOR HUGO
A23: 15 | B23: 02 | C23: 46174 | D23: 42121 | E23: 52.2 | G23: S | H23: 3.417 | I23: 01 | J23: FH02-599022 | K23: 46170 | L23: 46170 | M23: 20511004251 | Q23: PEAJE | AH23: =M23 -> 20511004251 | AI23: =IFERROR(INDEX(PROVEEDORES!$B$1:$B$6940,MATCH(AH23,PROVEEDORES!$A$1:$A$6940,0)),"") -> CONCESIONARIA IIRSA NORTE S.A.
A24: 15 | B24: 02 | C24: 46174 | D24: 42121 | E24: 52.2 | G24: S | H24: 3.417 | I24: 01 | J24: FH01-511089 | K24: 46166 | L24: 46166 | M24: 20511004251 | Q24: PEAJE | AH24: =M24 -> 20511004251 | AI24: =IFERROR(INDEX(PROVEEDORES!$B$1:$B$6940,MATCH(AH24,PROVEEDORES!$A$1:$A$6940,0)),"") -> CONCESIONARIA IIRSA NORTE S.A.
A25: 15 | B25: 02 | C25: 46174 | D25: 42121 | E25: 52.2 | G25: S | H25: 3.417 | I25: 01 | J25: FG01-670519 | K25: 46166 | L25: 46166 | M25: 20511004251 | Q25: PEAJE | AH25: =M25 -> 20511004251 | AI25: =IFERROR(INDEX(PROVEEDORES!$B$1:$B$6940,MATCH(AH25,PROVEEDORES!$A$1:$A$6940,0)),"") -> CONCESIONARIA IIRSA NORTE S.A.
A26: 15 | B26: 02 | C26: 46174 | D26: 42121 | E26: 52.2 | G26: S | H26: 3.417 | I26: 01 | J26: FE01-1273127 | K26: 46167 | L26: 46167 | M26: 20511004251 | Q26: PEAJE | AH26: =M26 -> 20511004251 | AI26: =IFERROR(INDEX(PROVEEDORES!$B$1:$B$6940,MATCH(AH26,PROVEEDORES!$A$1:$A$6940,0)),"") -> CONCESIONARIA IIRSA NORTE S.A.
A27: 15 | B27: 02 | C27: 46174 | D27: 42121 | E27: 52.2 | G27: S | H27: 3.417 | I27: 01 | J27: FF01-793241 | K27: 46167 | L27: 46167 | M27: 20511004251 | Q27: PEAJE | AH27: =M27 -> 20511004251 | AI27: =IFERROR(INDEX(PROVEEDORES!$B$1:$B$6940,MATCH(AH27,PROVEEDORES!$A$1:$A$6940,0)),"") -> CONCESIONARIA IIRSA NORTE S.A.
A28: 15 | B28: 02 | C28: 46174 | D28: 42121 | E28: 52.2 | G28: S | H28: 3.417 | I28: 01 | J28: FG02-684003 | K28: 46167 | L28: 46167 | M28: 20511004251 | Q28: PEAJE | AH28: =M28 -> 20511004251 | AI28: =IFERROR(INDEX(PROVEEDORES!$B$1:$B$6940,MATCH(AH28,PROVEEDORES!$A$1:$A$6940,0)),"") -> CONCESIONARIA IIRSA NORTE S.A.
A29: 15 | B29: 02 | C29: 46174 | D29: 42121 | E29: 30 | G29: S | H29: 3.417 | I29: 01 | J29: E001-2079 | K29: 46168 | L29: 46168 | M29: 10413807927 | Q29: ALOJAMIENTO | AH29: =M29 -> 10413807927 | AI29: =IFERROR(INDEX(PROVEEDORES!$B$1:$B$6940,MATCH(AH29,PROVEEDORES!$A$1:$A$6940,0)),"") -> REVILLA FUENTES JANETH MILENA
A30: 15 | B30: 02 | C30: 46174 | D30: 42121 | E30: 50 | G30: S | H30: 3.417 | I30: 01 | J30: E001-4181 | K30: 46170 | L30: 46170 | M30: 10439041701 | Q30: REPARACION DE LLANTA | AH30: =M30 -> 10439041701 | AI30: =IFERROR(INDEX(PROVEEDORES!$B$1:$B$6940,MATCH(AH30,PROVEEDORES!$A$1:$A$6940,0)),"") -> GUERRA SALAS ROMER
A31: 15 | B31: 02 | C31: 46174 | D31: 42121 | E31: 40 | G31: S | H31: 3.417 | I31: 01 | J31: FF01-4597 | K31: 46173 | L31: 46173 | M31: 10755996551 | Q31: LAVADO | AH31: =M31 -> 10755996551 | AI31: =IFERROR(INDEX(PROVEEDORES!$B$1:$B$6940,MATCH(AH31,PROVEEDORES!$A$1:$A$6940,0)),"") -> PEREZ DAHUA FRANS DENNIS
A32: 15 | B32: 02 | C32: 46174 | D32: 42121 | E32: 53 | G32: S | H32: 3.417 | I32: 01 | J32: FF01-4598 | K32: 46173 | L32: 46173 | M32: 10755996551 | Q32: ARREGLO DE CARGA | AH32: =M32 -> 10755996551 | AI32: =IFERROR(INDEX(PROVEEDORES!$B$1:$B$6940,MATCH(AH32,PROVEEDORES!$A$1:$A$6940,0)),"") -> PEREZ DAHUA FRANS DENNIS
A33: 15 | B33: 02 | C33: 46174 | D33: 6314 | E33: 40 | G33: S | H33: 3.417 | I33: 03 | J33: 0001-043546 | K33: 46162 | L33: 46162 | M33: 10446876312 | Q33: CONSUMO | AH33: =M33 -> 10446876312 | AI33: =IFERROR(INDEX(PROVEEDORES!$B$1:$B$6940,MATCH(AH33,PROVEEDORES!$A$1:$A$6940,0)),"") -> IRENE ELENITH ROJAS RUIZ
A34: 15 | B34: 02 | C34: 46174 | D34: 6314 | E34: 40 | G34: S | H34: 3.417 | I34: 03 | J34: 0001-043551 | K34: 46163 | L34: 46163 | M34: 10446876312 | Q34: CONSUMO | AH34: =M34 -> 10446876312 | AI34: =IFERROR(INDEX(PROVEEDORES!$B$1:$B$6940,MATCH(AH34,PROVEEDORES!$A$1:$A$6940,0)),"") -> IRENE ELENITH ROJAS RUIZ
... A45: 15 | B45: 02 | C45: 46174 | D45: 6314 | E45: 40 | G45: S | H45: 3.417 | I45: 03 | J45: 0001-043598 | K45: 46174 | L45: 46174 | M45: 10446876312 | Q45: CONSUMO | AH45: =M45 -> 10446876312 | AI45: =IFERROR(INDEX(PROVEEDORES!$B$1:$B$6940,MATCH(AH45,PROVEEDORES!$A$1:$A$6940,0)),"") -> IRENE ELENITH ROJAS RUIZ
A46: 15 | B46: 03 | C46: 46174 | D46: 14132 | F46: 650 | G46: S | H46: 3.417 | I46: PL | J46: 3613 | K46: 46164 | L46: 46164 | M46: 40018877 | Q46: RENGIFO/PUCALLPA-BAGUA-PUCALLPA/C8P765/EXCESO (0) | AH46: =M46 -> 40018877 | AI46: =IFERROR(INDEX(PROVEEDORES!$B$1:$B$6940,MATCH(AH46,PROVEEDORES!$A$1:$A$6940,0)),"") -> RENGIFO IGLESIAS HEBER
A47: 15 | B47: 03 | C47: 46174 | D47: 14132 | F47: 80 | G47: S | H47: 3.417 | I47: PL | J47: 3668 | K47: 46172 | L47: 46172 | M47: 40018877 | Q47: POR LIQUIDAR | AH47: =M47 -> 40018877 | AI47: =IFERROR(INDEX(PROVEEDORES!$B$1:$B$6940,MATCH(AH47,PROVEEDORES!$A$1:$A$6940,0)),"") -> RENGIFO IGLESIAS HEBER
A48: 15 | B48: 03 | C48: 46174 | D48: 14132 | F48: 234 | G48: S | H48: 3.417 | I48: PL | J48: 3687 | K48: 46174 | L48: 46174 | M48: 40018877 | Q48: POR LIQUIDAR | AH48: =M48 -> 40018877 | AI48: =IFERROR(INDEX(PROVEEDORES!$B$1:$B$6940,MATCH(AH48,PROVEEDORES!$A$1:$A$6940,0)),"") -> RENGIFO IGLESIAS HEBER
A49: 15 | B49: 03 | C49: 46174 | D49: 42121 | E49: 52.2 | G49: S | H49: 3.417 | I49: 01 | J49: FF01-794054 | K49: 46171 | L49: 46171 | M49: 20511004251 | Q49: PEAJE | AH49: =M49 -> 20511004251 | AI49: =IFERROR(INDEX(PROVEEDORES!$B$1:$B$6940,MATCH(AH49,PROVEEDORES!$A$1:$A$6940,0)),"") -> CONCESIONARIA IIRSA NORTE S.A.
A50: 15 | B50: 03 | C50: 46174 | D50: 42121 | E50: 52.2 | G50: S | H50: 3.417 | I50: 01 | J50: FH02-599380 | K50: 46172 | L50: 46172 | M50: 20511004251 | Q50: PEAJE | AH50: =M50 -> 20511004251 | AI50: =IFERROR(INDEX(PROVEEDORES!$B$1:$B$6940,MATCH(AH50,PROVEEDORES!$A$1:$A$6940,0)),"") -> CONCESIONARIA IIRSA NORTE S.A.
...

Sheet DATOS
A2: EJEMPLO
A3: POR LIQUIDAR EN EL HABER | E3: 14132
A4: BV DEBE | D4: 6314
A5: FT DEBE | D5: 42121
A7: CUENTA | B7: CONCEPTO | F7: TIPO DE DOCUMENTO
A8: 14131 | B8: LIQUIDACION LIMA | F8: 01 | G8: FACTURA
A9: 14132 | B9: LIQUIDACION PUCLLPA | F9: 02 | G9: RECIBO POR HONORARIO
A10: 141321 | B10: LIQUIDACION PUCLLPA (RRHH) | F10: 03 | G10: BOLETA DE VENTA
A11: 14133 | B11: LIQUIDACION TARAPOTO | F11: RI | G11: RECIBO DE INGRESO
A12: 141331 | B12: LIQUIDACION TARAPOTO (RRHH) | F12: PL | G12: POR LIQUIDAR
A13: 6314 | B13: POR CONSUMO
A14: 6313 | B14: ALOJAMIENTO
A15: 63433 | B15: LAVADO DE UNIDAD
A16: 63433 | B16: CAMBIO DE LLANTA
A17: 63433 | B17: AJUSTE DE LLANTA
A18: 63113 | B18: PEAJE
A19: 4241 | B19: CONCEPTO QUE INDIQUE
A20: 42121 | B20: CONCEPTO QUE INDIQUE

Sheet PROVEEDORES
A1: RUC O DNI | B1: RAZON SOCIAL | C1: APELLIDO 1 | D1: APELLIDO 2 | E1: NOMBRE 1 | F1: NOMBRE 2 | G1: TIPO
A2: 20494017955 | B2: "MULTISERVICIOS CALDERON V E.I.R.L." | G2: Proveedor
A3: 10218598361 | B3: ASTORAYME ORTIZ EDWIN ERACLIO | C3: ASTORAYME | D3: ORTIZ | E3: EDWIN | F3: ERACLIO | G3: Proveedor
A4: 10011660385 | B4: CASTILLO JIMENEZ JOSE ANTONIO | C4: CASTILLO | D4: JIMENEZ | E4: JOSE | F4: ANTONIO | G4: Proveedor
A5: 10337266750 | B5: IZQUIERDO PERALTA ERMILA | C5: IZQUIERDO | D5: PERALTA | E5: ERMILA | G5: Proveedor
A6: 10475916196 | B6: LEON TARAZONA ELMER LORENZO | C6: LEON | D6: TARAZONA | E6: ELMER | F6: LORENZO | G6: Proveedor
A7: 20601765234 | B7: OJOJOI E.I.R.L | G7: Proveedor
A8: 10448823500 | B8: PEÑA JUSTANO JUAN ABEL | C8: PEÑA | D8: JUSTANO | E8: JUAN | F8: ABEL | G8: Proveedor
A9: 10224959562 | B9: RETIS FANAN BONIFACIO | C9: RETIS | D9: FANAN | E9: BONIFACIO | G9: Proveedor
A10: 10224242021 | B10: ROJAS OCAMPO ANGELICA MARGARITA | C10: ROJAS | D10: OCAMPO | E10: ANGELICA | F10: MARGARITA | G10: Proveedor
A11: 10479390687 | B11: TAFUR BOGARIN INGRIS RULI | C11: TAFUR | D11: BOGARIN | E11: INGRIS | F11: RULI | G11: Proveedor
A12: 10001644667 | B12: TELLO GONZALEZ JUSTINIANO EDWIN | C12: TELLO | D12: GONZALEZ | E12: JUSTINIANO | F12: EDWIN | G12: Proveedor
A13: 20600611347 | B13: 20600611347.00 | G13: Proveedor
A14: 20601776767 | B14: 500 GRADOS S.A.C. | G14: Proveedor
A15: 20393772337 | B15: 9 DE OCTUBRE EMPRESA DE INVERSIONES TURISTICOS E.I.R.L. | G15: Proveedor
A16: 10466119534 | B16: ABAD ALEJANDRIA MANUEL | C16: ABAD | D16: ALEJANDRIA | E16: MANUEL | G16: Proveedor
A17: 10477136341 | B17: ABANTO CARRASCAL GRETY | C17: ABANTO | D17: CARRASCAL | E17: GRETY | G17: Proveedor
A18: 10189865797 | B18: ABANTO SALAS CIRIA IRAIDA | C18: ABANTO | D18: SALAS | E18: CIRIA | F18: IRAIDA | G18: Proveedor
A19: 10436985130 | B19: ABEL RAMIREZ TANANTA | C19: ABEL | D19: RAMIREZ | E19: TANANTA | G19: Proveedor
A20: 10200301906 | B20: ABREGU ARROYO DE ALVARADO YOLANDA | C20: ABREGU | D20: ARROYO | E20: YOLANDA | G20: Proveedor
A21: 20603743611 | B21: ACCESORIOS LA SOLUCION E.I.R.L. | G21: Proveedor
A22: 20446460481 | B22: ACERO COMERCIAL S.R.L. | G22: Proveedor
A23: 20393465329 | B23: ACEROS FLOVICSA SELVA S.A.C. | G23: Proveedor
A24: 10421133218 | B24: ACEVEDO CASTILLO CARLOS EMERSON | C24: ACEVEDO | D24: CASTILLO | E24: CARLOS | F24: EMERSON | G24: Proveedor
A25: 10421881575 | B25: ACOSTA RIOS MARIA ESTHER | C25: ACOSTA | D25: RIOS | E25: MARIA | F25: ESTHER | G25: Proveedor
A26: 10277322990 | B26: ACUNA FERNANDEZ MARIA AURORA | C26: MARIA | D26: AURORA | E26: ACUNA | F26: FERNANDEZ | G26: Proveedor
A27: 10482952424 | B27: ACUÑA FRANCO AGUSTIN | C27: ACUÑA | D27: FRANCO | E27: AGUSTIN | G27: Proveedor
A28: 10010344668 | B28: ACUÑA ZAGACETA SENAIDA CONSUELO | C28: ACUÑA | D28: ZAGACETA | E28: SENAIDA | F28: CONSUELO | G28: Proveedor
A29: 10431787861 | B29: ADAMS LOPEZ JIMI JAMES | C29: JIMI | D29: JAMES | E29: ADAMS | F29: LOPEZ | G29: Proveedor
A30: 00088151 | B30: ADAN LANFRANCO VASQUEZ | C30: ADAN | E30: LANFRANCO | F30: VASQUEZ | G30: Cliente
A31: 10802538028 | B31: ADELINDA MEJIA CABRERA | C31: MEJIA | D31: CABRERA | E31: ADELINDA | G31: Proveedor
A32: 10009668581 | B32: ADELMO IRENE SEGURA | C32: ADELMO | D32: IRENE | E32: SEGURA | G32: Proveedor
A33: 10435085291 | B33: ADRIANO MURGA ELVIS WIDMAN | C33: ADRIANO | D33: MURGA | E33: ELVIS | F33: WIDMAN | G33: Proveedor
A34: 10714795827 | B34: ADRIANZEN ARIAS LUIS EDUARDO | G34: Proveedor
A35: 10278235501 | B35: ADRIANZEN SOLANO ROSA ELVIRA | C35: ADRIANZEN | D35: SOLANO | E35: ROSA | F35: ELVIRA | G35: Proveedor
A36: 10405863591 | B36: ADRIANZEN VELASCO JULIO CESAR | C36: ADRIANZEN | D36: VELASCO | E36: JULIO | F36: CESAR | G36: Proveedor
A37: 20604013551 | B37: ADRIKA REVISIONES VEHICULARES SOCIEDAD ANÓNIMA CERRADA | G37: Proveedor
A38: 20568832664 | B38: AGRO FERRETERIA GAVINO S.A.C. | G38: Proveedor
A39: 20393686171 | B39: AGROINDUSTRIAS G. SHULLER E.I.R.L. | G39: Proveedor
A40: 20480650825 | B40: AGRONEGOCIOS & CIA S.A.C. | G40: Proveedor
...
